Workbook

Sheet Dashboard
A1: Concert for a Cure 2026 — Execution Dashboard
A2: Live view: pulls from Weekly Tracker tab
A4: Status Snapshot
A5: Total tasks | B5: =COUNTA('Weekly Tracker'!C5:C89) -> 85
A6: Done | B6: =COUNTIF('Weekly Tracker'!H5:H89,"Done") -> 0
A7: In Progress | B7: =COUNTIF('Weekly Tracker'!H5:H89,"In Progress") -> 1
A8: Blocked | B8: =COUNTIF('Weekly Tracker'!H5:H89,"Blocked") -> 0
A9: Not Started | B9: =COUNTIF('Weekly Tracker'!H5:H89,"Not Started") -> 84
A10: % Complete | B10: =IFERROR(COUNTIF('Weekly Tracker'!H5:H89,"Done")/COUNTA('Weekly Tracker'!C5:C89),0) -> 0
A11: Founder review items open | B11: =COUNTIFS('Weekly Tracker'!I5:I89,"Yes",'Weekly Tracker'!H5:H89,"<>Done") -> 60
A14: Workstream Breakdown
A15: Workstream | B15: Total | C15: Done | D15: % Complete
A16: Leadership | B16: =COUNTIF('Weekly Tracker'!B5:B89,A16) -> 3 | C16: =COUNTIFS('Weekly Tracker'!B5:B89,A16,'Weekly Tracker'!H5:H89,"Done") -> 0 | D16: =IFERROR(C16/B16,0) -> 0
A17: Fundraising | B17: =COUNTIF('Weekly Tracker'!B5:B89,A17) -> 13 | C17: =COUNTIFS('Weekly Tracker'!B5:B89,A17,'Weekly Tracker'!H5:H89,"Done") -> 0 | D17: =IFERROR(C17/B17,0) -> 0
A18: Auction | B18: =COUNTIF('Weekly Tracker'!B5:B89,A18) -> 2 | C18: =COUNTIFS('Weekly Tracker'!B5:B89,A18,'Weekly Tracker'!H5:H89,"Done") -> 0 | D18: =IFERROR(C18/B18,0) -> 0
A19: Food & Beverage | B19: =COUNTIF('Weekly Tracker'!B5:B89,A19) -> 6 | C19: =COUNTIFS('Weekly Tracker'!B5:B89,A19,'Weekly Tracker'!H5:H89,"Done") -> 0 | D19: =IFERROR(C19/B19,0) -> 0
A20: Entertainment | B20: =COUNTIF('Weekly Tracker'!B5:B89,A20) -> 5 | C20: =COUNTIFS('Weekly Tracker'!B5:B89,A20,'Weekly Tracker'!H5:H89,"Done") -> 0 | D20: =IFERROR(C20/B20,0) -> 0
A21: Tribute | B21: =COUNTIF('Weekly Tracker'!B5:B89,A21) -> 9 | C21: =COUNTIFS('Weekly Tracker'!B5:B89,A21,'Weekly Tracker'!H5:H89,"Done") -> 0 | D21: =IFERROR(C21/B21,0) -> 0
A22: Sponsors | B22: =COUNTIF('Weekly Tracker'!B5:B89,A22) -> 8 | C22: =COUNTIFS('Weekly Tracker'!B5:B89,A22,'Weekly Tracker'!H5:H89,"Done") -> 0 | D22: =IFERROR(C22/B22,0) -> 0
A23: Guest Experience | B23: =COUNTIF('Weekly Tracker'!B5:B89,A23) -> 3 | C23: =COUNTIFS('Weekly Tracker'!B5:B89,A23,'Weekly Tracker'!H5:H89,"Done") -> 0 | D23: =IFERROR(C23/B23,0) -> 0
A24: Venue | B24: =COUNTIF('Weekly Tracker'!B5:B89,A24) -> 3 | C24: =COUNTIFS('Weekly Tracker'!B5:B89,A24,'Weekly Tracker'!H5:H89,"Done") -> 0 | D24: =IFERROR(C24/B24,0) -> 0
A25: Photography | B25: =COUNTIF('Weekly Tracker'!B5:B89,A25) -> 3 | C25: =COUNTIFS('Weekly Tracker'!B5:B89,A25,'Weekly Tracker'!H5:H89,"Done") -> 0 | D25: =IFERROR(C25/B25,0) -> 0
A26: Volunteer Ops | B26: =COUNTIF('Weekly Tracker'!B5:B89,A26) -> 3 | C26: =COUNTIFS('Weekly Tracker'!B5:B89,A26,'Weekly Tracker'!H5:H89,"Done") -> 0 | D26: =IFERROR(C26/B26,0) -> 0
A27: MJFF / Kiera | B27: =COUNTIF('Weekly Tracker'!B5:B89,A27) -> 2 | C27: =COUNTIFS('Weekly Tracker'!B5:B89,A27,'Weekly Tracker'!H5:H89,"Done") -> 0 | D27: =IFERROR(C27/B27,0) -> 0
A28: Rentals | B28: =COUNTIF('Weekly Tracker'!B5:B89,A28) -> 1 | C28: =COUNTIFS('Weekly Tracker'!B5:B89,A28,'Weekly Tracker'!H5:H89,"Done") -> 0 | D28: =IFERROR(C28/B28,0) -> 0
A29: Run of Show | B29: =COUNTIF('Weekly Tracker'!B5:B89,A29) -> 3 | C29: =COUNTIFS('Weekly Tracker'!B5:B89,A29,'Weekly Tracker'!H5:H89,"Done") -> 0 | D29: =IFERROR(C29/B29,0) -> 0
A30: Setup | B30: =COUNTIF('Weekly Tracker'!B5:B89,A30) -> 4 | C30: =COUNTIFS('Weekly Tracker'!B5:B89,A30,'Weekly Tracker'!H5:H89,"Done") -> 0 | D30: =IFERROR(C30/B30,0) -> 0
A31: Execution | B31: =COUNTIF('Weekly Tracker'!B5:B89,A31) -> 11 | C31: =COUNTIFS('Weekly Tracker'!B5:B89,A31,'Weekly Tracker'!H5:H89,"Done") -> 0 | D31: =IFERROR(C31/B31,0) -> 0
A32: Logistics | B32: =COUNTIF('Weekly Tracker'!B5:B89,A32) -> 1 | C32: =COUNTIFS('Weekly Tracker'!B5:B89,A32,'Weekly Tracker'!H5:H89,"Done") -> 0 | D32: =IFERROR(C32/B32,0) -> 0
A33: Stewardship | B33: =COUNTIF('Weekly Tracker'!B5:B89,A33) -> 3 | C33: =COUNTIFS('Weekly Tracker'!B5:B89,A33,'Weekly Tracker'!H5:H89,"Done") -> 0 | D33: =IFERROR(C33/B33,0) -> 0
A34: Financials | B34: =COUNTIF('Weekly Tracker'!B5:B89,A34) -> 1 | C34: =COUNTIFS('Weekly Tracker'!B5:B89,A34,'Weekly Tracker'!H5:H89,"Done") -> 0 | D34: =IFERROR(C34/B34,0) -> 0
A35: Retrospective | B35: =COUNTIF('Weekly Tracker'!B5:B89,A35) -> 1 | C35: =COUNTIFS('Weekly Tracker'!B5:B89,A35,'Weekly Tracker'!H5:H89,"Done") -> 0 | D35: =IFERROR(C35/B35,0) -> 0

Sheet Weekly Tracker
A1: Concert for a Cure 2026 — Weekly Execution Tracker
A2: Event: Saturday, July 18, 2026 • 2:00–6:00 PM ET • Lakeside Home • 100 guests
A4: Week / Target Date | B4: Workstream | C4: Task | D4: Owner | E4: Support Person | F4: Deadline | G4: Dependency | H4: Status | I4: Founder Review Needed? | J4: Notes
A5: T-13 / Apr 20–26 | B5: Leadership | C5: Lock Master Operating Plan v2 as single source of truth; distribute to all leads | D5: Wendy | E5: — | F5: Apr 24 | G5: — | H5: In Progress | I5: Yes | J5: This tracker + v2 plan replaces prior versions
A6: T-13 / Apr 20–26 | B6: Leadership | C6: Schedule 30-min kickoff call with each of 5 leads (Hospitality, Volunteer Ops, Fundraising, Tribute, Sponsor) | D6: Wendy | E6: — | F6: Apr 26 | G6: Plan distributed | H6: Not Started | I6: Yes | J6: Walk them through their one-page brief
A7: T-13 / Apr 20–26 | B7: Fundraising | C7: Call Dan Abbott at Indy Boat Co — confirm boat lot, delivery timing, Rafflebox plan, speakerphone reveal moment | D7: Wendy + Rob | E7: — | F7: Apr 24 | G7: — | H7: Not Started | I7: Yes | J7: Founder-only relationship; no delegation
A8: T-13 / Apr 20–26 | B8: Fundraising | C8: Open Rafflebox account; configure boat raffle + 50/50 with Indiana charitable-gaming compliance | D8: Wendy | E8: Rafflebox support | F8: Apr 30 | G8: Boat lot confirmed with Dan | H8: Not Started | I8: Yes | J8: Ticket price, cap, draw date/time, T&Cs
A9: T-13 / Apr 20–26 | B9: Food & Beverage | C9: Shortlist 3 caterers; send RFP (heavy passed apps + 1 chef action station, lakeside, summer) | D9: Wendy | E9: Hospitality Lead (advisory) | F9: Apr 26 | G9: — | H9: Not Started | I9: Yes | J9: Wendy picks final; lead only advises on spec
A10: T-13 / Apr 20–26 | B10: Entertainment | C10: Shortlist 3 bands (pop / modern country trio or quartet); request demo reels + 18 July 18 quotes | D10: Wendy | E10: — | F10: Apr 26 | G10: — | H10: Not Started | I10: Yes | J10: Not a bar band; elevated lakeside energy
A11: T-13 / Apr 20–26 | B11: Tribute | C11: Design brief to Sallie Lord for Butterfly Wall — scale, palette, materials, placement in program zone | D11: Wendy | E11: Tribute Lead | F11: Apr 26 | G11: — | H11: Not Started | I11: Yes | J11: Architectural, not craft; photo-worthy
A12: T-12 / Apr 27–May 3 | B12: Fundraising | C12: Launch boat raffle public sales (Rafflebox link in newsletter, socials, Wendy's network) | D12: Wendy | E12: Comms partner | F12: May 1 | G12: Rafflebox configured | H12: Not Started | I12: Yes | J12: Pre-sell is the game; night-of is a bonus
A13: T-12 / Apr 27–May 3 | B13: Fundraising | C13: Launch 50/50 pre-sales on Rafflebox (or staged opening if state requires) | D13: Wendy | E13: Rafflebox support | F13: May 1 | G13: Rafflebox configured | H13: Not Started | I13: Yes | J13: Confirm IN charitable gaming compliance
A14: T-12 / Apr 27–May 3 | B14: Food & Beverage | C14: Collect caterer bids; taste session bookings if needed | D14: Wendy | E14: Hospitality Lead | F14: May 2 | G14: RFPs sent | H14: Not Started | I14: Yes
A15: T-12 / Apr 27–May 3 | B15: Entertainment | C15: Review demos; pick band; send contract | D15: Wendy | E15: — | F15: May 3 | G15: Demos received | H15: Not Started | I15: Yes | J15: $750 deposit typical
A16: T-12 / Apr 27–May 3 | B16: Tribute | C16: Sallie Lord design concepts reviewed; pick direction | D16: Wendy | E16: Tribute Lead | F16: May 3 | G16: Design brief sent | H16: Not Started | I16: Yes
A17: T-12 / Apr 27–May 3 | B17: Sponsors | C17: Finalize sponsor tiers: Title, Premium, Community — list target sponsors, dollar values, moments | D17: Wendy | E17: Sponsor Lead | F17: May 3 | G17: Plan v2 read | H17: Not Started | I17: Yes | J17: Moments not logos
A18: T-11 / May 4–10 | B18: Food & Beverage | C18: Select caterer; sign contract; lock headcount at 100 + 10% buffer | D18: Wendy | E18: — | F18: May 8 | G18: Bids in | H18: Not Started | I18: Yes | J18: Wendy signs
A19: T-11 / May 4–10 | B19: Food & Beverage | C19: Beverage order: 42 bottles Veuve Clicquot Yellow Label, 2 cases backup prosecco | D19: Wendy | E19: Hospitality Lead | F19: May 8 | G19: — | H19: Not Started | I19: Yes | J19: Veuve for welcome + toast only
A20: T-11 / May 4–10 | B20: Food & Beverage | C20: Beverage order: premium wines (3 cs white, 2 cs rosé, 2 cs red), premium spirits, beer, NA line | D20: Wendy | E20: Hospitality Lead | F20: May 8 | G20: — | H20: Not Started | I20: Yes | J20: See Plan §9 beverage spec
A21: T-11 / May 4–10 | B21: Entertainment | C21: Band contract signed + deposit paid; set times locked (see ROS) | D21: Wendy | E21: — | F21: May 8 | G21: Band chosen | H21: Not Started | I21: Yes
A22: T-11 / May 4–10 | B22: Tribute | C22: Sallie Lord — greenlight materials + begin sourcing/fabrication | D22: Wendy | E22: Tribute Lead | F22: May 10 | G22: Concept selected | H22: Not Started | I22: Yes
A23: T-11 / May 4–10 | B23: Sponsors | C23: Send tailored sponsor decks to top prospects | D23: Sponsor Lead | E23: Wendy | F23: May 10 | G23: Tiers locked | H23: Not Started | I23: No | J23: Wendy closes big ones
A24: T-11 / May 4–10 | B24: Fundraising | C24: Secure auctioneer for live auction lot + paddle raise (professional, nonprofit experience) | D24: Wendy | E24: — | F24: May 10 | G24: — | H24: Not Started | I24: Yes
A25: T-10 / May 11–17 | B25: Auction | C25: Confirm single live auction lot: Lakeside Weekend — lock dates, amenities, photo package | D25: Wendy | E25: — | F25: May 15 | G25: — | H25: Not Started | I25: Yes | J25: Cut to 1 lot; fewer/better
A26: T-10 / May 11–17 | B26: Fundraising | C26: Rafflebox pre-sale push #1: MJFF-aligned donor list email + social carousel | D26: Wendy | E26: Comms partner | F26: May 15 | G26: Raffle live | H26: Not Started | I26: No
A27: T-10 / May 11–17 | B27: Guest Experience | C27: Send Save-the-Dates if not already sent; confirm guest list at 100 | D27: Wendy | E27: — | F27: May 15 | G27: — | H27: Not Started | I27: Yes
A28: T-10 / May 11–17 | B28: Venue | C28: Tent rental booked (confirm pool deck tent + backyard program tent); lighting spec sent | D28: Wendy | E28: Hospitality Lead | F28: May 17 | G28: — | H28: Not Started | I28: Yes | J28: Weather backup baked in
A29: T-10 / May 11–17 | B29: Photography | C29: Hire photographer + videographer (half-day each); share 12 must-capture moments list | D29: Wendy | E29: — | F29: May 17 | G29: Plan v2 read | H29: Not Started | I29: Yes | J29: No one hired yet
A30: T-9 / May 18–24 | B30: Sponsors | C30: Close 2 of 3 Title-level sponsors | D30: Wendy | E30: Sponsor Lead | F30: May 24 | G30: Decks sent | H30: Not Started | I30: Yes
A31: T-9 / May 18–24 | B31: Sponsors | C31: Close Premium tier sponsors (bar, tent, print) | D31: Sponsor Lead | E31: Wendy | F31: May 24 | G31: Decks sent | H31: Not Started | I31: No
A32: T-9 / May 18–24 | B32: Rentals | C32: Tables, chairs, linen, glassware, bar build-out order placed | D32: Hospitality Lead | E32: Wendy | F32: May 22 | G32: Caterer signed | H32: Not Started | I32: No | J32: Linen palette per Plan
A33: T-9 / May 18–24 | B33: Tribute | C33: Check-in envelope design (name card + We Connect card + butterfly tag + program) — send to print | D33: Tribute Lead | E33: Wendy | F33: May 24 | G33: — | H33: Not Started | I33: Yes | J33: Wendy approves final proof
A34: T-9 / May 18–24 | B34: MJFF / Kiera | C34: Confirm Kiera travel, arrival time, speaking slot (4:05, 7 min), AV needs | D34: Wendy | E34: — | F34: May 24 | G34: — | H34: Not Started | I34: Yes | J34: Most important external speaker
A35: T-8 / May 25–31 | B35: Fundraising | C35: Raffle push #2: Dan + boat photo hero content; video w/ Dan's story | D35: Wendy + Rob | E35: Comms partner | F35: May 31 | G35: Pre-sale #1 live | H35: Not Started | I35: Yes
A36: T-8 / May 25–31 | B36: Guest Experience | C36: RSVPs close-in tracking; chase non-responders personally | D36: Wendy | E36: — | F36: May 31 | G36: Invites sent | H36: Not Started | I36: Yes
A37: T-8 / May 25–31 | B37: Sponsors | C37: Collect sponsor logos + bios for printed program + signage | D37: Sponsor Lead | E37: — | F37: May 31 | G37: Sponsors closed | H37: Not Started | I37: No
A38: T-8 / May 25–31 | B38: Volunteer Ops | C38: Recruit 4 volunteers (Floor Captain, Check-In, Butterfly, Raffle); send briefs | D38: Volunteer Ops Lead | E38: Wendy | F38: May 31 | G38: — | H38: Not Started | I38: Yes | J38: Only 4 total
A39: T-8 / May 25–31 | B39: Photography | C39: Photographer + videographer walk-through of property (shot list + lighting windows) | D39: Wendy | E39: — | F39: May 31 | G39: Team hired | H39: Not Started | I39: No
A40: T-7 / Jun 1–7 | B40: Auction | C40: Live auction lot collateral finalized (photo card, bid card, auctioneer script) | D40: Wendy | E40: Fundraising Lead | F40: Jun 5 | G40: Lot confirmed | H40: Not Started | I40: Yes
A41: T-7 / Jun 1–7 | B41: Fundraising | C41: Paddle raise script drafted (emotional build → ask → release); Wendy review | D41: Fundraising Lead | E41: Wendy | F41: Jun 5 | G41: — | H41: Not Started | I41: Yes | J41: See ROS 4:12–4:38
...

Sheet Founder-Only Decisions
A1: Founder-Only Decisions — Wendy Owns These
A2: Decisions that cannot be delegated — tone, money, relationships, Sue's memory
A4: Decision | B4: Why Founder-Only | C4: Target Date | D4: Status | E4: Notes
A5: Caterer selection | B5: Food is the guest-experience backbone; Wendy's taste, Sue's legacy | C5: May 8 | D5: Not Started | E5: Hospitality Lead advises only
A6: Band selection | B6: Tone of entire event — pop/modern country, not bar band | C6: May 3 | D6: Not Started
A7: Boat raffle partnership w/ Dan Abbott | B7: Personal relationship + Rob's; Indy Boat Co is the marquee lot | C7: Apr 24 (kickoff) | D7: Not Started | E7: Wendy + Rob own; no delegation
A8: Butterfly Wall design direction (Sallie Lord) | B8: Honors Sue; architectural statement, not craft | C8: Apr 26 brief / May 3 direction | D8: Not Started
A9: Sue tribute language (toast, Veuve cue, signage copy) | B9: Sacred, emotional; only Wendy's voice | C9: Jun 7 | D9: Not Started
A10: Live auction lot — Lakeside Weekend confirmation | B10: Single marquee lot; fewer/better | C10: May 15 | D10: Not Started
A11: Paddle raise ask ladder ($5K to $100) | B11: Fundraising math; donor psychology | C11: Jun 21 | D11: Not Started
A12: Title-tier sponsor partners (top 2–3) | B12: Strategic relationship | C12: May 24 | D12: Not Started | E12: Lead can close premium + community
A13: Kiera (MJFF) speaking slot & tone brief | B13: Credibility anchor; 4:05 slot | C13: Jun 21 | D13: Not Started
A14: Guest list & hospitality tone (tight, elevated, warm) | B14: Curated not broad | C14: May 15 | D14: Not Started
A15: Photographer + videographer hire | B15: Memory capture; no one hired yet | C15: May 17 | D15: Not Started
A16: Beverage order (Veuve + premium program) | B16: Veuve is Sue's — cannot be wrong | C16: May 8 | D16: Not Started | E16: 42 bottles + prosecco backup
A17: Any last-minute scope change or cut | B17: Protects the Sue Test | C17: Ongoing | D17: Not Started

Sheet Delegate Now
A1: Delegate Now — Tasks to Hand Off This Week
A2: What to move off Wendy's plate immediately to free up founder attention
A4: Task | B4: Delegate To | C4: Briefing Needed | D4: Deadline | E4: Status | F4: Notes
A5: Lead caterer RFP logistics (emails, quote collection, comparison spreadsheet) | B5: Hospitality Lead | C5: Spec sheet + 3 caterer shortlist | D5: Apr 30 | E5: Not Started | F5: Wendy picks final
A6: Sponsor prospect outreach (Premium + Community tiers) | B6: Sponsor Lead | C6: Deck + tier list + moment map | D6: May 3 start | E6: Not Started | F6: Wendy closes Title tier only
A7: Volunteer recruitment (4 volunteers) | B7: Volunteer Ops Lead | C7: 4 role briefs from Plan v2 | D7: May 31 | E7: Not Started
A8: Butterfly Wall fabrication logistics (after concept approved) | B8: Tribute Lead w/ Sallie Lord | C8: Wendy's design direction + timeline | D8: Jun 14 check-in | E8: Not Started
A9: Rentals order (tables, chairs, linen, glassware, bar build) | B9: Hospitality Lead | C9: Guest count + aesthetic palette | D9: May 22 | E9: Not Started
A10: Signage & print coordination (programs, bar menus, sponsor boards) | B10: Sponsor Lead + Tribute Lead | C10: Design system + sponsor logos | D10: Jun 7 | E10: Not Started | F10: Wendy approves proofs
A11: Volunteer walkthrough + on-site briefing | B11: Volunteer Ops Lead | C11: ROS + radio plan | D11: Jul 12 | E11: Not Started
A12: Vendor load-in schedule | B12: Hospitality Lead | C12: Final vendor list + timing | D12: Jul 15 | E12: Not Started
A13: Raffle + 50/50 comms push copy (Wendy voice notes, lead writes) | B13: Comms partner | C13: Tone + facts brief | D13: Ongoing | E13: Not Started | F13: Wendy approves each send
A14: Parking + valet logistics | B14: Hospitality Lead | C14: Neighborhood map + overflow plan | D14: Jun 7 | E14: Not Started
A15: Program printing + assembly (envelopes, name cards, butterfly tags) | B15: Tribute Lead + volunteer | C15: Proofs approved | D15: Jun 28 | E15: Not Started

Sheet Vendor-Owned
A1: Vendor-Owned Responsibilities
A2: Professional vendors own execution; Wendy sets vision, approves proofs, signs contracts
A4: Vendor | B4: Owns | C4: Contract Signed By | D4: Fee / Budget | E4: Contact | F4: Notes
A5: Caterer (TBD) | B5: Menu design, passed apps, action station, kitchen run, service staff, clean-up | C5: May 8 | D5: TBD | E5: TBD | F5: Wendy picks
A6: Band (TBD — pop/modern country) | B6: Live music afternoon + cocktail + post-program; PA, zones, silence cue | C6: May 3 | D6: ~$3,500–5,500 | E6: TBD | F6: Trio or quartet
A7: Tent + rentals | B7: Tent raising, sides, lighting, tables, chairs, linen, glassware | C7: May 17 | D7: TBD | E7: TBD | F7: Weather backup
A8: Florist | B8: Arrangements for program zone, bar, butterfly wall anchor, send-off | C8: Jun 1 | D8: TBD | E8: TBD | F8: Palette per Plan
A9: Photographer | B9: Half-day coverage, 12 must-capture moments, portraits | C9: May 17 | D9: ~$1,500–2,500 | E9: TBD | F9: None hired yet
A10: Videographer | B10: Half-day coverage, highlight reel (2–3 min), Wendy thank-you cut | C10: May 17 | D10: ~$1,500–2,500 | E10: TBD | F10: None hired yet
A11: Auctioneer | B11: Live auction lot + paddle raise; pro nonprofit experience | C11: May 10 | D11: TBD (some comp) | E11: TBD
A12: Sallie Lord (creative lead) | B12: Butterfly Wall design + install; tribute staging; aesthetic direction | C12: Relationship-based | D12: In-kind or fee | E12: Direct | F12: Creative partner, not vendor
A13: Rafflebox | B13: Boat raffle + 50/50 platform; RNG draw; compliance support | C13: Apr 30 | D13: % fee | E13: Rafflebox account | F13: IN charitable gaming
A14: Indy Boat Co (Dan Abbott) | B14: Boat donation, pickup logistics, speakerphone reveal moment | C14: Apr 24 (verbal) | D14: In-kind | E14: Dan direct | F14: Wendy + Rob own
A15: Valet / parking | B15: Lane direction, parking flow, overflow lot, signage | C15: Jun 7 | D15: TBD | E15: TBD
A16: Print shop | B16: Envelopes, name cards, butterfly tags, signage, sponsor boards | C16: Jun 7 | D16: TBD | E16: TBD
A17: MJFF (Kiera) | B17: Credibility anchor speaker, $2,500 event-experience contribution | C17: Already confirmed | D17: In-kind + $2,500 | E17: Kiera direct
